<?xml version="1.0"?>
<sdf version="1.5">
  <model name="Turtlebot4_standard">
    <plugin name="slotcar" filename="libslotcar.so">

      <!-- Forward / Backward -->
      <nominal_drive_speed>0.31</nominal_drive_speed>
      <nominal_drive_acceleration>0.25</nominal_drive_acceleration>
      <max_drive_acceleration>0.75</max_drive_acceleration>
      
      <!-- Turning -->
      <nominal_turn_speed>0.6</nominal_turn_speed>
      <nominal_turn_acceleration>1.5</nominal_turn_acceleration>
      <max_turn_acceleration>2.0</max_turn_acceleration>
    
      <!-- Stop distance and radius -->
      <stop_distance>0.1</stop_distance>
      <stop_radius>0.1</stop_radius>
    
      <!-- Can the robot drive backwards -->
      <reversible>true</reversible> 
    
      <!-- Battery params -->
      <nominal_voltage>24.0</nominal_voltage>
      <nominal_capacity>40.0</nominal_capacity>
      <charging_current>8.8</charging_current>
    
      <!-- Physical params -->
      <mass>3.9</mass> 
      <inertia>40.0</inertia>
      <friction_coefficient>0.22</friction_coefficient>
      
      <!-- Power systems -->
      <nominal_power>20.0</nominal_power>
    
    </plugin>
    
    
    <link name="rack">
      <inertial>
        <pose>0.001453 -0.000453 0.029787 0 0 0</pose>
        <inertia>
          <ixx>0.058640</ixx>
          <ixy>0.000124</ixy>
          <ixz>0.000615</ixz>
          <iyy>0.058786</iyy>
          <iyz>0.000014</iyz>
          <izz>1.532440</izz>
        </inertia>
        <mass>2.234000</mass>
      </inertial>
      <collision name="plate_0_collision">
        <pose>-0.043340 0 0.084757 0 0 0</pose>
        <geometry>
          <box>
            <size>0.233502 0.314845 0.006401</size>
          </box>
        </geometry>
      </collision>
      <visual name="plate_0_visual">
        <pose>-0.043340 0 0.084757 0 0 0</pose>
        <geometry>
          <mesh>
            <uri>model://Turtlebot4_standard/meshes/plate_0_logo.dae</uri>
          </mesh>
        </geometry>
      </visual>
      <collision name="plate_1_collision">
        <pose>-0.002660 0 0.141907 0 0 0</pose>
        <geometry>
          <box>
            <size>0.314856 0.314856 0.006401</size>
          </box>
        </geometry>
      </collision>
      <visual name="plate_1_visual">
        <pose>-0.002660 0 0.141907 0 0 0</pose>
        <geometry>
          <mesh>
            <uri>model://Turtlebot4_standard/meshes/plate_1_logo.dae</uri>
          </mesh>
        </geometry>
      </visual>
      <collision name="plate_2_collision">
        <pose>-0.002660 0 0.199108 0 0 0</pose>
        <geometry>
          <box>
            <size>0.314856 0.314856 0.006401</size>
          </box>
        </geometry>
      </collision>
      <visual name="plate_2_visual">
        <pose>-0.002660 0 0.199108 0 0 0</pose>
        <geometry>
          <mesh>
            <uri>model://Turtlebot4_standard/meshes/plate_1_logo.dae</uri>
          </mesh>
        </geometry>
      </visual>
      <collision name="plate_3_collision">
        <pose>-0.015820 0 0.405457 0 0 0</pose>
        <geometry>
          <box>
            <size>0.288000 0.315000 0.006401</size>
          </box>
        </geometry>
      </collision>
      <visual name="plate_3_visual">
        <pose>-0.015820 0 0.405457 0 0 0</pose>
        <geometry>
          <mesh>
            <uri>model://Turtlebot4_standard/meshes/plate_2_logo.dae</uri>
          </mesh>
        </geometry>
      </visual>
      <collision name="spacer_0_collision">
        <pose>-0.002540 0.111468 0.079992 0 0 0</pose>
        <geometry>
          <cylinder>
            <radius>0.012700</radius>
            <length>0.003175</length>
          </cylinder>
        </geometry>
      </collision>
      <visual name="spacer_0_visual">
        <pose>-0.002540 0.111468 0.079992 0 0 0</pose>
        <geometry>
          <mesh>
            <uri>model://Turtlebot4_standard/meshes/68-02403-125_Spacer.dae</uri>
          </mesh>
        </geometry>
      </visual>
      <collision name="spacer_1_collision">
        <pose>-0.002540 -0.111468 0.079992 0 0 0</pose>
        <geometry>
          <cylinder>
            <radius>0.012700</radius>
            <length>0.003175</length>
          </cylinder>
        </geometry>
      </collision>
      <visual name="spacer_1_visual">
        <pose>-0.002540 -0.111468 0.079992 0 0 0</pose>
        <geometry>
          <mesh>
            <uri>model://Turtlebot4_standard/meshes/68-02403-125_Spacer.dae</uri>
          </mesh>
        </geometry>
      </visual>
      <collision name="spacer_2_collision">
        <pose>-0.072390 -0.111468 0.079992 0 0 0</pose>
        <geometry>
          <cylinder>
            <radius>0.012700</radius>
            <length>0.003175</length>
          </cylinder>
        </geometry>
      </collision>
      <visual name="spacer_2_visual">
        <pose>-0.072390 -0.111468 0.079992 0 0 0</pose>
        <geometry>
          <mesh>
            <uri>model://Turtlebot4_standard/meshes/68-02403-125_Spacer.dae</uri>
          </mesh>
        </geometry>
      </visual>
      <collision name="spacer_3_collision">
        <pose>-0.072390 0.111468 0.079992 0 0 0</pose>
        <geometry>
          <cylinder>
            <radius>0.012700</radius>
            <length>0.003175</length>
          </cylinder>
        </geometry>
      </collision>
      <visual name="spacer_3_visual">
        <pose>-0.072390 0.111468 0.079992 0 0 0</pose>
        <geometry>
          <mesh>
            <uri>model://Turtlebot4_standard/meshes/68-02403-125_Spacer.dae</uri>
          </mesh>
        </geometry>
      </visual>
      <collision name="standoff_2in_0_collision">
        <pose>0.067640 0.131420 0.087980 0 0 0</pose>
        <geometry>
          <cylinder>
            <radius>0.038100</radius>
            <length>0.063500</length>
          </cylinder>
        </geometry>
      </collision>
      <visual name="standoff_2in_0_visual">
        <pose>0.067640 0.131420 0.087980 0 0 0</pose>
        <geometry>
          <mesh>
            <uri>model://Turtlebot4_standard/meshes/68-04552-2000-RA_Turtlebot_M-F_Standoff.dae</uri>
          </mesh>
        </geometry>
      </visual>
      <collision name="standoff_2in_1_collision">
        <pose>0.067640 -0.131420 0.087980 0 0 0</pose>
        <geometry>
          <cylinder>
            <radius>0.038100</radius>
            <length>0.063500</length>
          </cylinder>
        </geometry>
      </collision>
      <visual name="standoff_2in_1_visual">
        <pose>0.067640 -0.131420 0.087980 0 0 0</pose>
        <geometry>
          <mesh>
            <uri>model://Turtlebot4_standard/meshes/68-04552-2000-RA_Turtlebot_M-F_Standoff.dae</uri>
          </mesh>
        </geometry>
      </visual>
      <collision name="standoff_2in_2_collision">
        <pose>-0.052832 -0.131420 0.087980 0 0 0</pose>
        <geometry>
          <cylinder>
            <radius>0.038100</radius>
            <length>0.063500</length>
          </cylinder>
        </geometry>
      </collision>
      <visual name="standoff_2in_2_visual">
        <pose>-0.052832 -0.131420 0.087980 0 0 0</pose>
        <geometry>
          <mesh>
            <uri>model://Turtlebot4_standard/meshes/68-04552-2000-RA_Turtlebot_M-F_Standoff.dae</uri>
          </mesh>
        </geometry>
      </visual>
      <collision name="standoff_2in_3_collision">
        <pose>-0.052832 0.131420 0.087980 0 0 0</pose>
        <geometry>
          <cylinder>
            <radius>0.038100</radius>
            <length>0.063500</length>
          </cylinder>
        </geometry>
      </collision>
      <visual name="standoff_2in_3_visual">
        <pose>-0.052832 0.131420 0.087980 0 0 0</pose>
        <geometry>
          <mesh>
            <uri>model://Turtlebot4_standard/meshes/68-04552-2000-RA_Turtlebot_M-F_Standoff.dae</uri>
          </mesh>
        </geometry>
      </visual>
      <collision name="standoff_2in_4_collision">
        <pose>0.067640 0.131420 0.145130 0 0 0</pose>
        <geometry>
          <cylinder>
            <radius>0.038100</radius>
            <length>0.063500</length>
          </cylinder>
        </geometry>
      </collision>
      <visual name="standoff_2in_4_visual">
        <pose>0.067640 0.131420 0.145130 0 0 0</pose>
        <geometry>
          <mesh>
            <uri>model://Turtlebot4_standard/meshes/68-04552-2000-RA_Turtlebot_M-F_Standoff.dae</uri>
          </mesh>
        </geometry>
      </visual>
      <collision name="standoff_2in_5_collision">
        <pose>0.067640 -0.131420 0.145130 0 0 0</pose>
        <geometry>
          <cylinder>
            <radius>0.038100</radius>
            <length>0.063500</length>
          </cylinder>
        </geometry>
      </collision>
      <visual name="standoff_2in_5_visual">
        <pose>0.067640 -0.131420 0.145130 0 0 0</pose>
        <geometry>
          <mesh>
            <uri>model://Turtlebot4_standard/meshes/68-04552-2000-RA_Turtlebot_M-F_Standoff.dae</uri>
          </mesh>
        </geometry>
      </visual>
      <collision name="standoff_2in_6_collision">
        <pose>-0.052832 -0.131420 0.145130 0 0 0</pose>
        <geometry>
          <cylinder>
            <radius>0.038100</radius>
            <length>0.063500</length>
          </cylinder>
        </geometry>
      </collision>
      <visual name="standoff_2in_6_visual">
        <pose>-0.052832 -0.131420 0.145130 0 0 0</pose>
        <geometry>
          <mesh>
            <uri>model://Turtlebot4_standard/meshes/68-04552-2000-RA_Turtlebot_M-F_Standoff.dae</uri>
          </mesh>
        </geometry>
      </visual>
      <collision name="standoff_2in_7_collision">
        <pose>-0.052832 0.131420 0.145130 0 0 0</pose>
        <geometry>
          <cylinder>
            <radius>0.038100</radius>
            <length>0.063500</length>
          </cylinder>
        </geometry>
      </collision>
      <visual name="standoff_2in_7_visual">
        <pose>-0.052832 0.131420 0.145130 0 0 0</pose>
        <geometry>
          <mesh>
            <uri>model://Turtlebot4_standard/meshes/68-04552-2000-RA_Turtlebot_M-F_Standoff.dae</uri>
          </mesh>
        </geometry>
      </visual>
      <collision name="standoff_8in_0_collision">
        <pose>0.067640 0.131420 0.202280 0 0 0</pose>
        <geometry>
          <cylinder>
            <radius>0.011113</radius>
            <length>0.203200</length>
          </cylinder>
        </geometry>
      </collision>
      <visual name="standoff_8in_0_visual">
        <pose>0.067640 0.131420 0.202280 0 0 0</pose>
        <geometry>
          <mesh>
            <uri>model://Turtlebot4_standard/meshes/68-02421-8000-RA_Turtlebot_F-F_Standoff.dae</uri>
          </mesh>
        </geometry>
      </visual>
      <collision name="standoff_8in_1_collision">
        <pose>0.067640 -0.131420 0.202280 0 0 0</pose>
        <geometry>
          <cylinder>
            <radius>0.011113</radius>
            <length>0.203200</length>
          </cylinder>
        </geometry>
      </collision>
      <visual name="standoff_8in_1_visual">
        <pose>0.067640 -0.131420 0.202280 0 0 0</pose>
        <geometry>
          <mesh>
            <uri>model://Turtlebot4_standard/meshes/68-02421-8000-RA_Turtlebot_F-F_Standoff.dae</uri>
          </mesh>
        </geometry>
      </visual>
      <collision name="standoff_8in_2_collision">
        <pose>-0.052832 -0.131420 0.202280 0 0 0</pose>
        <geometry>
          <cylinder>
            <radius>0.011113</radius>
            <length>0.203200</length>
          </cylinder>
        </geometry>
      </collision>
      <visual name="standoff_8in_2_visual">
        <pose>-0.052832 -0.131420 0.202280 0 0 0</pose>
        <geometry>
          <mesh>
            <uri>model://Turtlebot4_standard/meshes/68-02421-8000-RA_Turtlebot_F-F_Standoff.dae</uri>
          </mesh>
        </geometry>
      </visual>
      <collision name="standoff_8in_3_collision">
        <pose>-0.052832 0.131420 0.202280 0 0 0</pose>
        <geometry>
          <cylinder>
            <radius>0.011113</radius>
            <length>0.203200</length>
          </cylinder>
        </geometry>
      </collision>
      <visual name="standoff_8in_3_visual">
        <pose>-0.052832 0.131420 0.202280 0 0 0</pose>
        <geometry>
          <mesh>
            <uri>model://Turtlebot4_standard/meshes/68-02421-8000-RA_Turtlebot_F-F_Standoff.dae</uri>
          </mesh>
        </geometry>
      </visual>
      <collision name="standoff_kinect_0_collision">
        <pose>-0.105098 0.098000 0.202308 0 0 0</pose>
        <geometry>
          <cylinder>
            <radius>0.001111</radius>
            <length>0.008585</length>
          </cylinder>
        </geometry>
      </collision>
      <visual name="standoff_kinect_0_visual">
        <pose>-0.105098 0.098000 0.202308 0 0 0</pose>
        <geometry>
          <mesh>
            <uri>model://Turtlebot4_standard/meshes/68-04556-RA_Kinect_Standoff_Assy.dae</uri>
          </mesh>
        </geometry>
      </visual>
      <collision name="standoff_kinect_1_collision">
        <pose>-0.105098 -0.098000 0.202308 0 0 0</pose>
        <geometry>
          <cylinder>
            <radius>0.001111</radius>
            <length>0.008585</length>
          </cylinder>
        </geometry>
      </collision>
      <visual name="standoff_kinect_1_visual">
        <pose>-0.105098 -0.098000 0.202308 0 0 0</pose>
        <geometry>
          <mesh>
            <uri>model://Turtlebot4_standard/meshes/68-04556-RA_Kinect_Standoff_Assy.dae</uri>
          </mesh>
        </geometry>
      </visual>
      <sensor name="laser" type="ray">
        <pose>-0.065000 0 0.092000 0 0 0</pose>
        <ray>
          <scan>
            <horizontal>
              <samples>180</samples>
              <resolution>1.000000</resolution>
              <min_angle>-2.268928</min_angle>
              <max_angle>2.268928</max_angle>
            </horizontal>
          </scan>
          <range>
            <min>0.080000</min>
            <max>10</max>
            <resolution>0.010000</resolution>
          </range>
        </ray>
        <update_rate>20</update_rate>
      </sensor>
    </link>
    <link name="base">
      <inertial>
        <pose>0.001453 -0.000453 0.029787 0 0 0</pose>
        <inertia>
          <ixx>0.058640</ixx>
          <ixy>0.000124</ixy>
          <ixz>0.000615</ixz>
          <iyy>0.058786</iyy>
          <iyz>0.000014</iyz>
          <izz>1.532440</izz>
        </inertia>
        <mass>2.234000</mass>
      </inertial>
      <collision name="base_collision">
        <pose>0 0 0.047800 0 0 0</pose>
        <geometry>
          <cylinder>
            <radius>0.016495</radius>
            <length>0.061163</length>
          </cylinder>
        </geometry>
      </collision>
      <visual name="base_visual">
        <pose>0 0 0.047800 0 0 0</pose>
        <geometry>
          <mesh>
            <uri>model://create/meshes/create_body.dae</uri>
          </mesh>
        </geometry>
      </visual>
      <collision name="front_wheel_collision">
        <pose>0.130000 0 0.017000 0 1.570700 1.570700</pose>
        <geometry>
          <sphere>
            <radius>0.018000</radius>
          </sphere>
        </geometry>
        <surface>
          <friction>
            <ode>
              <mu>0</mu>
              <mu2>0</mu2>
              <fdir1>0 0 0</fdir1>
              <slip1>0</slip1>
              <slip2>0</slip2>
            </ode>
          </friction>
        </surface>
      </collision>
      <visual name="front_wheel_visual">
        <pose>0.130000 0 0.017000 0 1.570700 1.570700</pose>
        <geometry>
          <sphere>
            <radius>0.009000</radius>
          </sphere>
        </geometry>
      </visual>
      <collision name="rear_wheel_collision">
        <pose>-0.13 0 0.017 0 1.5707 1.5707</pose>
        <geometry>
          <sphere>
            <radius>0.015000</radius>
          </sphere>
        </geometry>
        <surface>
          <friction>
            <ode>
              <mu>0</mu>
              <mu2>0</mu2>
              <fdir1>0 0 0</fdir1>
              <slip1>0</slip1>
              <slip2>0</slip2>
            </ode>
          </friction>
        </surface>
      </collision>
      <visual name="rear_wheel_visual">
        <pose>-0.130000 0 0.017000 0 1.570700 1.570700</pose>
        <geometry>
          <sphere>
            <radius>0.007500</radius>
          </sphere>
        </geometry>
      </visual>
      <sensor name="left_cliff_sensor" type="ray">
        <pose>0.070000 0.140000 0.027000 0 1.570790 0</pose>
        <ray>
          <scan>
            <horizontal>
              <samples>1</samples>
              <resolution>1.000000</resolution>
              <min_angle>0</min_angle>
              <max_angle>0</max_angle>
            </horizontal>
          </scan>
          <range>
            <min>0.010000</min>
            <max>0.040000</max>
            <resolution>0.100000</resolution>
          </range>
        </ray>
      </sensor>
      <sensor name="leftfront_cliff_sensor" type="ray">
        <pose>0.150000 0.040000 0.027000 0 1.570790 0</pose>
        <ray>
          <scan>
            <horizontal>
              <samples>1</samples>
              <resolution>1.000000</resolution>
              <min_angle>0</min_angle>
              <max_angle>0</max_angle>
            </horizontal>
          </scan>
          <range>
            <min>0.010000</min>
            <max>0.040000</max>
            <resolution>0.100000</resolution>
          </range>
        </ray>
      </sensor>
      <sensor name="right_cliff_sensor" type="ray">
        <pose>0.070000 -0.140000 0.027000 0 1.570790 0</pose>
        <ray>
          <scan>
            <horizontal>
              <samples>1</samples>
              <resolution>1.000000</resolution>
              <min_angle>0</min_angle>
              <max_angle>0</max_angle>
            </horizontal>
          </scan>
          <range>
            <min>0.010000</min>
            <max>0.040000</max>
            <resolution>0.100000</resolution>
          </range>
        </ray>
      </sensor>
      <sensor name="rightfront_cliff_sensor" type="ray">
        <pose>0.150000 -0.040000 0.027000 0 1.570790 0</pose>
        <ray>
          <scan>
            <horizontal>
              <samples>1</samples>
              <resolution>1.000000</resolution>
              <min_angle>0</min_angle>
              <max_angle>0</max_angle>
            </horizontal>
          </scan>
          <range>
            <min>0.010000</min>
            <max>0.040000</max>
            <resolution>0.100000</resolution>
          </range>
        </ray>
      </sensor>
      <sensor name="wall_sensor" type="ray">
        <pose>0.090000 -0.120000 0.059000 0 0 -1.000000</pose>
        <ray>
          <scan>
            <horizontal>
              <samples>1</samples>
              <resolution>1.000000</resolution>
              <min_angle>0</min_angle>
              <max_angle>0</max_angle>
            </horizontal>
          </scan>
          <range>
            <min>0.016000</min>
            <max>0.040000</max>
            <resolution>0.100000</resolution>
          </range>
        </ray>
      </sensor>
    </link>
    <link name="left_wheel">
      <pose>0 0.130000 0.032000 0 0 0</pose>
      <inertial>
        <inertia>
          <ixx>0.001000</ixx>
          <ixy>0</ixy>
          <ixz>0</ixz>
          <iyy>0.001000</iyy>
          <iyz>0</iyz>
          <izz>0.001000</izz>
        </inertia>
        <mass>0.010000</mass>
      </inertial>
      <collision name="collision">
        <pose>0 0 0 0 1.570700 1.570700</pose>
        <geometry>
          <cylinder>
            <radius>0.033000</radius>
            <length>0.023000</length>
          </cylinder>
        </geometry>
        <surface>
          <friction>
            <ode>
              <mu>10</mu>
              <mu2>10</mu2>
              <fdir1>0 0 0</fdir1>
              <slip1>0</slip1>
              <slip2>0</slip2>
            </ode>
          </friction>
        </surface>
      </collision>
      <visual name="visual">
        <pose>0 0 0 0 1.570700 1.570700</pose>
        <geometry>
          <cylinder>
            <radius>0.033000</radius>
            <length>0.023000</length>
          </cylinder>
        </geometry>
      </visual>
    </link>
    <link name="right_wheel">
      <pose>0 -0.130000 0.032000 0 0 0</pose>
      <inertial>
        <inertia>
          <ixx>0.001000</ixx>
          <ixy>0</ixy>
          <ixz>0</ixz>
          <iyy>0.001000</iyy>
          <iyz>0</iyz>
          <izz>0.001000</izz>
        </inertia>
        <mass>0.010000</mass>
      </inertial>
      <collision name="collision">
        <pose>0 0 0 0 1.570700 1.570700</pose>
        <geometry>
          <cylinder>
            <radius>0.033000</radius>
            <length>0.023000</length>
          </cylinder>
        </geometry>
        <surface>
          <friction>
            <ode>
              <mu>10</mu>
              <mu2>10</mu2>
              <fdir1>0 0 0</fdir1>
              <slip1>0</slip1>
              <slip2>0</slip2>
            </ode>
          </friction>
        </surface>
      </collision>
      <visual name="visual">
        <pose>0 0 0 0 1.570700 1.570700</pose>
        <geometry>
          <cylinder>
            <radius>0.033000</radius>
            <length>0.023000</length>
          </cylinder>
        </geometry>
      </visual>
    </link>
    <joint name="joint_tire_left" type="revolute">
      <parent>base</parent>
      <child>left_wheel</child>
      <axis>
        <xyz>0 1 0</xyz>
        <use_parent_model_frame>true</use_parent_model_frame>
      </axis>
    </joint>
    <joint name="joint_tire_right" type="revolute">
      <parent>base</parent>
      <child>right_wheel</child>
      <axis>
        <xyz>0 1 0</xyz>
        <use_parent_model_frame>true</use_parent_model_frame>
      </axis>
    </joint>
    <include>
      <uri>model://kinect</uri>
      <pose>-0.087098 0 0.303857 0 0 0</pose>
    </include>
    <joint name="create_rack" type="revolute">
      <parent>base</parent>
      <child>rack</child>
      <axis>
        <xyz>0 0 1</xyz>
        <limit>
          <lower>0</lower>
          <upper>0</upper>
        </limit>
        <use_parent_model_frame>true</use_parent_model_frame>
      </axis>
    </joint>
    <joint name="kinect_rack" type="revolute">
      <parent>kinect::link</parent>
      <child>rack</child>
      <axis>
        <xyz>0 0 1</xyz>
        <limit>
          <lower>0</lower>
          <upper>0</upper>
        </limit>
        <use_parent_model_frame>true</use_parent_model_frame>
      </axis>
    </joint>
  </model>
</sdf>